Workbook
Name Slicer_City: #N/A
Name Slicer_Department: #N/A
Name Slicer_Experience_Group: #N/A
Name Slicer_Gender: #N/A
Name Slicer_Performance_Rating: #N/A
Name Slicer_Salary_Band: #N/A

Sheet Dataset
A1: Employee ID | B1: Employee Name | C1: Department | D1: Gender | E1: Age | F1: Salary | G1: Experience | H1: Joining Date | I1: City | J1: Performance Rating | K1: Attrition | L1: Experience Group | M1: Salary Band | N1: Age Group | O1: Join Year | P1: Join Month | Q1: Bonus % | R1: Bonus Amount | S1: Total Salary | T1: Employee Status | U1: Salary Grade | V1: Experience Level
A2: EMP0001 | B2: Sonia Verma | C2: R&D | D2: Female | E2: 26 | F2: 48412 | G2: 7 | H2: 29-Jun-2020 | I2: Delhi | J2: Very Good | K2: No | L2: {=_xlfn.IFS(HR_Data[[#This Row],[Experience]]<2,"0-2 Years",HR_Data[[#This Row],[Experience]]<5,"2-5 Years",HR_Data[[#This Row],[Experience]]<10,"5-10 Years",TRUE(),"10+ Years")} -> 5-10 Years | M2: {=_xlfn.IFS(HR_Data[[#This Row],[Salary]]<40000,"Low",HR_Data[[#This Row],[Salary]]<70000,"Medium",HR_Data[[#This Row],[Salary]]<100000,"High",TRUE(),"Very High")} -> Medium | N2: {=_xlfn.IFS(HR_Data[[#This Row],[Age]]<25,"18-24",HR_Data[[#This Row],[Age]]<35,"25-34",HR_Data[[#This Row],[Age]]<45,"35-44",TRUE(),"45+")} -> 25-34 | O2: =YEAR(HR_Data[[#This Row],[Joining Date]]) -> 2020 | P2: =TEXT(HR_Data[[#This Row],[Joining Date]],"mmmm") -> June | Q2: {=_xlfn.IFS(HR_Data[[#This Row],[Performance Rating]]="Excellent",20%,HR_Data[[#This Row],[Performance Rating]]="Very Good",15%,HR_Data[[#This Row],[Performance Rating]]="Good",10%,HR_Data[[#This Row],[Performance Rating]]="Average",5%,TRUE(),0%)} -> 0.15 | R2: =HR_Data[[#This Row],[Salary]]*HR_Data[[#This Row],[Bonus %]] -> 7261.8 | S2: =HR_Data[[#This Row],[Salary]]+HR_Data[[#This Row],[Bonus Amount]] -> 55673.8 | T2: =IF(HR_Data[[#This Row],[Attrition]]="Yes","Inactive","Active") -> Active | U2: {=_xlfn.IFS(HR_Data[[#This Row],[Salary]]>=100000,"A",HR_Data[[#This Row],[Salary]]>=70000,"B",HR_Data[[#This Row],[Salary]]>=50000,"C",TRUE(),"D")} -> D | V2: {=_xlfn.IFS(HR_Data[[#This Row],[Experience]]>=15,"Expert",HR_Data[[#This Row],[Experience]]>=8,"Senior",HR_Data[[#This Row],[Experience]]>=3,"Mid-Level",TRUE(),"Junior")} -> Mid-Level
A3: EMP0002 | B3: Ankit Jain | C3: Admin | D3: Male | E3: 21 | F3: 27364 | G3: 1 | H3: 20-Mar-2020 | I3: Lucknow | J3: Good | K3: Yes | L3: {=_xlfn.IFS(HR_Data[[#This Row],[Experience]]<2,"0-2 Years",HR_Data[[#This Row],[Experience]]<5,"2-5 Years",HR_Data[[#This Row],[Experience]]<10,"5-10 Years",TRUE(),"10+ Years")} -> 0-2 Years | M3: {=_xlfn.IFS(HR_Data[[#This Row],[Salary]]<40000,"Low",HR_Data[[#This Row],[Salary]]<70000,"Medium",HR_Data[[#This Row],[Salary]]<100000,"High",TRUE(),"Very High")} -> Low | N3: {=_xlfn.IFS(HR_Data[[#This Row],[Age]]<25,"18-24",HR_Data[[#This Row],[Age]]<35,"25-34",HR_Data[[#This Row],[Age]]<45,"35-44",TRUE(),"45+")} -> 18-24 | O3: =YEAR(HR_Data[[#This Row],[Joining Date]]) -> 2020 | P3: =TEXT(HR_Data[[#This Row],[Joining Date]],"mmmm") -> March | Q3: {=_xlfn.IFS(HR_Data[[#This Row],[Performance Rating]]="Excellent",20%,HR_Data[[#This Row],[Performance Rating]]="Very Good",15%,HR_Data[[#This Row],[Performance Rating]]="Good",10%,HR_Data[[#This Row],[Performance Rating]]="Average",5%,TRUE(),0%)} -> 0.1 | R3: =HR_Data[[#This Row],[Salary]]*HR_Data[[#This Row],[Bonus %]] -> 2736.4 | S3: =HR_Data[[#This Row],[Salary]]+HR_Data[[#This Row],[Bonus Amount]] -> 30100.4 | T3: =IF(HR_Data[[#This Row],[Attrition]]="Yes","Inactive","Active") -> Inactive | U3: {=_xlfn.IFS(HR_Data[[#This Row],[Salary]]>=100000,"A",HR_Data[[#This Row],[Salary]]>=70000,"B",HR_Data[[#This Row],[Salary]]>=50000,"C",TRUE(),"D")} -> D | V3: {=_xlfn.IFS(HR_Data[[#This Row],[Experience]]>=15,"Expert",HR_Data[[#This Row],[Experience]]>=8,"Senior",HR_Data[[#This Row],[Experience]]>=3,"Mid-Level",TRUE(),"Junior")} -> Junior
A4: EMP0003 | B4: Vikas Verma | C4: IT | D4: Female | E4: 36 | F4: 76631 | G4: 17 | H4: 24-Jun-2024 | I4: Mumbai | J4: Very Good | K4: No | L4: {=_xlfn.IFS(HR_Data[[#This Row],[Experience]]<2,"0-2 Years",HR_Data[[#This Row],[Experience]]<5,"2-5 Years",HR_Data[[#This Row],[Experience]]<10,"5-10 Years",TRUE(),"10+ Years")} -> 10+ Years | M4: {=_xlfn.IFS(HR_Data[[#This Row],[Salary]]<40000,"Low",HR_Data[[#This Row],[Salary]]<70000,"Medium",HR_Data[[#This Row],[Salary]]<100000,"High",TRUE(),"Very High")} -> High | N4: {=_xlfn.IFS(HR_Data[[#This Row],[Age]]<25,"18-24",HR_Data[[#This Row],[Age]]<35,"25-34",HR_Data[[#This Row],[Age]]<45,"35-44",TRUE(),"45+")} -> 35-44 | O4: =YEAR(HR_Data[[#This Row],[Joining Date]]) -> 2024 | P4: =TEXT(HR_Data[[#This Row],[Joining Date]],"mmmm") -> June | Q4: {=_xlfn.IFS(HR_Data[[#This Row],[Performance Rating]]="Excellent",20%,HR_Data[[#This Row],[Performance Rating]]="Very Good",15%,HR_Data[[#This Row],[Performance Rating]]="Good",10%,HR_Data[[#This Row],[Performance Rating]]="Average",5%,TRUE(),0%)} -> 0.15 | R4: =HR_Data[[#This Row],[Salary]]*HR_Data[[#This Row],[Bonus %]] -> 11494.65 | S4: =HR_Data[[#This Row],[Salary]]+HR_Data[[#This Row],[Bonus Amount]] -> 88125.65 | T4: =IF(HR_Data[[#This Row],[Attrition]]="Yes","Inactive","Active") -> Active | U4: {=_xlfn.IFS(HR_Data[[#This Row],[Salary]]>=100000,"A",HR_Data[[#This Row],[Salary]]>=70000,"B",HR_Data[[#This Row],[Salary]]>=50000,"C",TRUE(),"D")} -> B | V4: {=_xlfn.IFS(HR_Data[[#This Row],[Experience]]>=15,"Expert",HR_Data[[#This Row],[Experience]]>=8,"Senior",HR_Data[[#This Row],[Experience]]>=3,"Mid-Level",TRUE(),"Junior")} -> Expert
A5: EMP0004 | B5: Sonia Verma | C5: Admin | D5: Male | E5: 46 | F5: 107182 | G5: 22 | H5: 06-Dec-2020 | I5: Kolkata | J5: Average | K5: No | L5: {=_xlfn.IFS(HR_Data[[#This Row],[Experience]]<2,"0-2 Years",HR_Data[[#This Row],[Experience]]<5,"2-5 Years",HR_Data[[#This Row],[Experience]]<10,"5-10 Years",TRUE(),"10+ Years")} -> 10+ Years | M5: {=_xlfn.IFS(HR_Data[[#This Row],[Salary]]<40000,"Low",HR_Data[[#This Row],[Salary]]<70000,"Medium",HR_Data[[#This Row],[Salary]]<100000,"High",TRUE(),"Very High")} -> Very High | N5: {=_xlfn.IFS(HR_Data[[#This Row],[Age]]<25,"18-24",HR_Data[[#This Row],[Age]]<35,"25-34",HR_Data[[#This Row],[Age]]<45,"35-44",TRUE(),"45+")} -> 45+ | O5: =YEAR(HR_Data[[#This Row],[Joining Date]]) -> 2020 | P5: =TEXT(HR_Data[[#This Row],[Joining Date]],"mmmm") -> December | Q5: {=_xlfn.IFS(HR_Data[[#This Row],[Performance Rating]]="Excellent",20%,HR_Data[[#This Row],[Performance Rating]]="Very Good",15%,HR_Data[[#This Row],[Performance Rating]]="Good",10%,HR_Data[[#This Row],[Performance Rating]]="Average",5%,TRUE(),0%)} -> 0.05 | R5: =HR_Data[[#This Row],[Salary]]*HR_Data[[#This Row],[Bonus %]] -> 5359.1 | S5: =HR_Data[[#This Row],[Salary]]+HR_Data[[#This Row],[Bonus Amount]] -> 112541.1 | T5: =IF(HR_Data[[#This Row],[Attrition]]="Yes","Inactive","Active") -> Active | U5: {=_xlfn.IFS(HR_Data[[#This Row],[Salary]]>=100000,"A",HR_Data[[#This Row],[Salary]]>=70000,"B",HR_Data[[#This Row],[Salary]]>=50000,"C",TRUE(),"D")} -> A | V5: {=_xlfn.IFS(HR_Data[[#This Row],[Experience]]>=15,"Expert",HR_Data[[#This Row],[Experience]]>=8,"Senior",HR_Data[[#This Row],[Experience]]>=3,"Mid-Level",TRUE(),"Junior")} -> Expert
A6: EMP0005 | B6: Pooja Patel | C6: IT | D6: Male | E6: 47 | F6: 86450 | G6: 18 | H6: 25-Apr-2019 | I6: Mumbai | J6: Good | K6: Yes | L6: {=_xlfn.IFS(HR_Data[[#This Row],[Experience]]<2,"0-2 Years",HR_Data[[#This Row],[Experience]]<5,"2-5 Years",HR_Data[[#This Row],[Experience]]<10,"5-10 Years",TRUE(),"10+ Years")} -> 10+ Years | M6: {=_xlfn.IFS(HR_Data[[#This Row],[Salary]]<40000,"Low",HR_Data[[#This Row],[Salary]]<70000,"Medium",HR_Data[[#This Row],[Salary]]<100000,"High",TRUE(),"Very High")} -> High | N6: {=_xlfn.IFS(HR_Data[[#This Row],[Age]]<25,"18-24",HR_Data[[#This Row],[Age]]<35,"25-34",HR_Data[[#This Row],[Age]]<45,"35-44",TRUE(),"45+")} -> 45+ | O6: =YEAR(HR_Data[[#This Row],[Joining Date]]) -> 2019 | P6: =TEXT(HR_Data[[#This Row],[Joining Date]],"mmmm") -> April | Q6: {=_xlfn.IFS(HR_Data[[#This Row],[Performance Rating]]="Excellent",20%,HR_Data[[#This Row],[Performance Rating]]="Very Good",15%,HR_Data[[#This Row],[Performance Rating]]="Good",10%,HR_Data[[#This Row],[Performance Rating]]="Average",5%,TRUE(),0%)} -> 0.1 | R6: =HR_Data[[#This Row],[Salary]]*HR_Data[[#This Row],[Bonus %]] -> 8645 | S6: =HR_Data[[#This Row],[Salary]]+HR_Data[[#This Row],[Bonus Amount]] -> 95095 | T6: =IF(HR_Data[[#This Row],[Attrition]]="Yes","Inactive","Active") -> Inactive | U6: {=_xlfn.IFS(HR_Data[[#This Row],[Salary]]>=100000,"A",HR_Data[[#This Row],[Salary]]>=70000,"B",HR_Data[[#This Row],[Salary]]>=50000,"C",TRUE(),"D")} -> B | V6: {=_xlfn.IFS(HR_Data[[#This Row],[Experience]]>=15,"Expert",HR_Data[[#This Row],[Experience]]>=8,"Senior",HR_Data[[#This Row],[Experience]]>=3,"Mid-Level",TRUE(),"Junior")} -> Expert
A7: EMP0006 | B7: Rahul Verma | C7: R&D | D7: Male | E7: 47 | F7: 108657 | G7: 24 | H7: 08-Mar-2023 | I7: Kolkata | J7: Very Good | K7: No | L7: {=_xlfn.IFS(HR_Data[[#This Row],[Experience]]<2,"0-2 Years",HR_Data[[#This Row],[Experience]]<5,"2-5 Years",HR_Data[[#This Row],[Experience]]<10,"5-10 Years",TRUE(),"10+ Years")} -> 10+ Years | M7: {=_xlfn.IFS(HR_Data[[#This Row],[Salary]]<40000,"Low",HR_Data[[#This Row],[Salary]]<70000,"Medium",HR_Data[[#This Row],[Salary]]<100000,"High",TRUE(),"Very High")} -> Very High | N7: {=_xlfn.IFS(HR_Data[[#This Row],[Age]]<25,"18-24",HR_Data[[#This Row],[Age]]<35,"25-34",HR_Data[[#This Row],[Age]]<45,"35-44",TRUE(),"45+")} -> 45+ | O7: =YEAR(HR_Data[[#This Row],[Joining Date]]) -> 2023 | P7: =TEXT(HR_Data[[#This Row],[Joining Date]],"mmmm") -> March | Q7: {=_xlfn.IFS(HR_Data[[#This Row],[Performance Rating]]="Excellent",20%,HR_Data[[#This Row],[Performance Rating]]="Very Good",15%,HR_Data[[#This Row],[Performance Rating]]="Good",10%,HR_Data[[#This Row],[Performance Rating]]="Average",5%,TRUE(),0%)} -> 0.15 | R7: =HR_Data[[#This Row],[Salary]]*HR_Data[[#This Row],[Bonus %]] -> 16298.55 | S7: =HR_Data[[#This Row],[Salary]]+HR_Data[[#This Row],[Bonus Amount]] -> 124955.55 | T7: =IF(HR_Data[[#This Row],[Attrition]]="Yes","Inactive","Active") -> Active | U7: {=_xlfn.IFS(HR_Data[[#This Row],[Salary]]>=100000,"A",HR_Data[[#This Row],[Salary]]>=70000,"B",HR_Data[[#This Row],[Salary]]>=50000,"C",TRUE(),"D")} -> A | V7: {=_xlfn.IFS(HR_Data[[#This Row],[Experience]]>=15,"Expert",HR_Data[[#This Row],[Experience]]>=8,"Senior",HR_Data[[#This Row],[Experience]]>=3,"Mid-Level",TRUE(),"Junior")} -> Expert
A8: EMP0007 | B8: Sonia Gupta | C8: Operations | D8: Male | E8: 36 | F8: 80147 | G8: 15 | H8: 06-Jul-2023 | I8: Pune | J8: Very Good | K8: No | L8: {=_xlfn.IFS(HR_Data[[#This Row],[Experience]]<2,"0-2 Years",HR_Data[[#This Row],[Experience]]<5,"2-5 Years",HR_Data[[#This Row],[Experience]]<10,"5-10 Years",TRUE(),"10+ Years")} -> 10+ Years | M8: {=_xlfn.IFS(HR_Data[[#This Row],[Salary]]<40000,"Low",HR_Data[[#This Row],[Salary]]<70000,"Medium",HR_Data[[#This Row],[Salary]]<100000,"High",TRUE(),"Very High")} -> High | N8: {=_xlfn.IFS(HR_Data[[#This Row],[Age]]<25,"18-24",HR_Data[[#This Row],[Age]]<35,"25-34",HR_Data[[#This Row],[Age]]<45,"35-44",TRUE(),"45+")} -> 35-44 | O8: =YEAR(HR_Data[[#This Row],[Joining Date]]) -> 2023 | P8: =TEXT(HR_Data[[#This Row],[Joining Date]],"mmmm") -> July | Q8: {=_xlfn.IFS(HR_Data[[#This Row],[Performance Rating]]="Excellent",20%,HR_Data[[#This Row],[Performance Rating]]="Very Good",15%,HR_Data[[#This Row],[Performance Rating]]="Good",10%,HR_Data[[#This Row],[Performance Rating]]="Average",5%,TRUE(),0%)} -> 0.15 | R8: =HR_Data[[#This Row],[Salary]]*HR_Data[[#This Row],[Bonus %]] -> 12022.05 | S8: =HR_Data[[#This Row],[Salary]]+HR_Data[[#This Row],[Bonus Amount]] -> 92169.05 | T8: =IF(HR_Data[[#This Row],[Attrition]]="Yes","Inactive","Active") -> Active | U8: {=_xlfn.IFS(HR_Data[[#This Row],[Salary]]>=100000,"A",HR_Data[[#This Row],[Salary]]>=70000,"B",HR_Data[[#This Row],[Salary]]>=50000,"C",TRUE(),"D")} -> B | V8: {=_xlfn.IFS(HR_Data[[#This Row],[Experience]]>=15,"Expert",HR_Data[[#This Row],[Experience]]>=8,"Senior",HR_Data[[#This Row],[Experience]]>=3,"Mid-Level",TRUE(),"Junior")} -> Expert
A9: EMP0008 | B9: Mohit Yadav | C9: Sales | D9: Female | E9: 26 | F9: 36545 | G9: 2 | H9: 02-Jan-2021 | I9: Jaipur | J9: Excellent | K9: No | L9: {=_xlfn.IFS(HR_Data[[#This Row],[Experience]]<2,"0-2 Years",HR_Data[[#This Row],[Experience]]<5,"2-5 Years",HR_Data[[#This Row],[Experience]]<10,"5-10 Years",TRUE(),"10+ Years")} -> 2-5 Years | M9: {=_xlfn.IFS(HR_Data[[#This Row],[Salary]]<40000,"Low",HR_Data[[#This Row],[Salary]]<70000,"Medium",HR_Data[[#This Row],[Salary]]<100000,"High",TRUE(),"Very High")} -> Low | N9: {=_xlfn.IFS(HR_Data[[#This Row],[Age]]<25,"18-24",HR_Data[[#This Row],[Age]]<35,"25-34",HR_Data[[#This Row],[Age]]<45,"35-44",TRUE(),"45+")} -> 25-34 | O9: =YEAR(HR_Data[[#This Row],[Joining Date]]) -> 2021 | P9: =TEXT(HR_Data[[#This Row],[Joining Date]],"mmmm") -> January | Q9: {=_xlfn.IFS(HR_Data[[#This Row],[Performance Rating]]="Excellent",20%,HR_Data[[#This Row],[Performance Rating]]="Very Good",15%,HR_Data[[#This Row],[Performance Rating]]="Good",10%,HR_Data[[#This Row],[Performance Rating]]="Average",5%,TRUE(),0%)} -> 0.2 | R9: =HR_Data[[#This Row],[Salary]]*HR_Data[[#This Row],[Bonus %]] -> 7309 | S9: =HR_Data[[#This Row],[Salary]]+HR_Data[[#This Row],[Bonus Amount]] -> 43854 | T9: =IF(HR_Data[[#This Row],[Attrition]]="Yes","Inactive","Active") -> Active | U9: {=_xlfn.IFS(HR_Data[[#This Row],[Salary]]>=100000,"A",HR_Data[[#This Row],[Salary]]>=70000,"B",HR_Data[[#This Row],[Salary]]>=50000,"C",TRUE(),"D")} -> D | V9: {=_xlfn.IFS(HR_Data[[#This Row],[Experience]]>=15,"Expert",HR_Data[[#This Row],[Experience]]>=8,"Senior",HR_Data[[#This Row],[Experience]]>=3,"Mid-Level",TRUE(),"Junior")} -> Junior
A10: EMP0009 | B10: Rahul Kumar | C10: Admin | D10: Female | E10: 50 | F10: 118479 | G10: 29 | H10: 17-Feb-2018 | I10: Chennai | J10: Very Good | K10: No | L10: {=_xlfn.IFS(HR_Data[[#This Row],[Experience]]<2,"0-2 Years",HR_Data[[#This Row],[Experience]]<5,"2-5 Years",HR_Data[[#This Row],[Experience]]<10,"5-10 Years",TRUE(),"10+ Years")} -> 10+ Years | M10: {=_xlfn.IFS(HR_Data[[#This Row],[Salary]]<40000,"Low",HR_Data[[#This Row],[Salary]]<70000,"Medium",HR_Data[[#This Row],[Salary]]<100000,"High",TRUE(),"Very High")} -> Very High | N10: {=_xlfn.IFS(HR_Data[[#This Row],[Age]]<25,"18-24",HR_Data[[#This Row],[Age]]<35,"25-34",HR_Data[[#This Row],[Age]]<45,"35-44",TRUE(),"45+")} -> 45+ | O10: =YEAR(HR_Data[[#This Row],[Joining Date]]) -> 2018 | P10: =TEXT(HR_Data[[#This Row],[Joining Date]],"mmmm") -> February | Q10: {=_xlfn.IFS(HR_Data[[#This Row],[Performance Rating]]="Excellent",20%,HR_Data[[#This Row],[Performance Rating]]="Very Good",15%,HR_Data[[#This Row],[Performance Rating]]="Good",10%,HR_Data[[#This Row],[Performance Rating]]="Average",5%,TRUE(),0%)} -> 0.15 | R10: =HR_Data[[#This Row],[Salary]]*HR_Data[[#This Row],[Bonus %]] -> 17771.85 | S10: =HR_Data[[#This Row],[Salary]]+HR_Data[[#This Row],[Bonus Amount]] -> 136250.85 | T10: =IF(HR_Data[[#This Row],[Attrition]]="Yes","Inactive","Active") -> Active | U10: {=_xlfn.IFS(HR_Data[[#This Row],[Salary]]>=100000,"A",HR_Data[[#This Row],[Salary]]>=70000,"B",HR_Data[[#This Row],[Salary]]>=50000,"C",TRUE(),"D")} -> A | V10: {=_xlfn.IFS(HR_Data[[#This Row],[Experience]]>=15,"Expert",HR_Data[[#This Row],[Experience]]>=8,"Senior",HR_Data[[#This Row],[Experience]]>=3,"Mid-Level",TRUE(),"Junior")} -> Expert
A11: EMP0010 | B11: Neha Singh | C11: Finance | D11: Female | E11: 35 | F11: 78496 | G11: 14 | H11: 25-Jan-2026 | I11: Ahmedabad | J11: Excellent | K11: Yes | L11: {=_xlfn.IFS(HR_Data[[#This Row],[Experience]]<2,"0-2 Years",HR_Data[[#This Row],[Experience]]<5,"2-5 Years",HR_Data[[#This Row],[Experience]]<10,"5-10 Years",TRUE(),"10+ Years")} -> 10+ Years | M11: {=_xlfn.IFS(HR_Data[[#This Row],[Salary]]<40000,"Low",HR_Data[[#This Row],[Salary]]<70000,"Medium",HR_Data[[#This Row],[Salary]]<100000,"High",TRUE(),"Very High")} -> High | N11: {=_xlfn.IFS(HR_Data[[#This Row],[Age]]<25,"18-24",HR_Data[[#This Row],[Age]]<35,"25-34",HR_Data[[#This Row],[Age]]<45,"35-44",TRUE(),"45+")} -> 35-44 | O11: =YEAR(HR_Data[[#This Row],[Joining Date]]) -> 2026 | P11: =TEXT(HR_Data[[#This Row],[Joining Date]],"mmmm") -> January | Q11: {=_xlfn.IFS(HR_Data[[#This Row],[Performance Rating]]="Excellent",20%,HR_Data[[#This Row],[Performance Rating]]="Very Good",15%,HR_Data[[#This Row],[Performance Rating]]="Good",10%,HR_Data[[#This Row],[Performance Rating]]="Average",5%,TRUE(),0%)} -> 0.2 | R11: =HR_Data[[#This Row],[Salary]]*HR_Data[[#This Row],[Bonus %]] -> 15699.2 | S11: =HR_Data[[#This Row],[Salary]]+HR_Data[[#This Row],[Bonus Amount]] -> 94195.2 | T11: =IF(HR_Data[[#This Row],[Attrition]]="Yes","Inactive","Active") -> Inactive | U11: {=_xlfn.IFS(HR_Data[[#This Row],[Salary]]>=100000,"A",HR_Data[[#This Row],[Salary]]>=70000,"B",HR_Data[[#This Row],[Salary]]>=50000,"C",TRUE(),"D")} -> B | V11: {=_xlfn.IFS(HR_Data[[#This Row],[Experience]]>=15,"Expert",HR_Data[[#This Row],[Experience]]>=8,"Senior",HR_Data[[#This Row],[Experience]]>=3,"Mid-Level",TRUE(),"Junior")} -> Senior
A12: EMP0011 | B12: Aman Verma | C12: Legal | D12: Female | E12: 29 | F12: 42304 | G12: 4 | H12: 01-Jul-2025 | I12: Chennai | J12: Good | K12: No | L12: {=_xlfn.IFS(HR_Data[[#This Row],[Experience]]<2,"0-2 Years",HR_Data[[#This Row],[Experience]]<5,"2-5 Years",HR_Data[[#This Row],[Experience]]<10,"5-10 Years",TRUE(),"10+ Years")} -> 2-5 Years | M12: {=_xlfn.IFS(HR_Data[[#This Row],[Salary]]<40000,"Low",HR_Data[[#This Row],[Salary]]<70000,"Medium",HR_Data[[#This Row],[Salary]]<100000,"High",TRUE(),"Very High")} -> Medium | N12: {=_xlfn.IFS(HR_Data[[#This Row],[Age]]<25,"18-24",HR_Data[[#This Row],[Age]]<35,"25-34",HR_Data[[#This Row],[Age]]<45,"35-44",TRUE(),"45+")} -> 25-34 | O12: =YEAR(HR_Data[[#This Row],[Joining Date]]) -> 2025 | P12: =TEXT(HR_Data[[#This Row],[Joining Date]],"mmmm") -> July | Q12: {=_xlfn.IFS(HR_Data[[#This Row],[Performance Rating]]="Excellent",20%,HR_Data[[#This Row],[Performance Rating]]="Very Good",15%,HR_Data[[#This Row],[Performance Rating]]="Good",10%,HR_Data[[#This Row],[Performance Rating]]="Average",5%,TRUE(),0%)} -> 0.1 | R12: =HR_Data[[#This Row],[Salary]]*HR_Data[[#This Row],[Bonus %]] -> 4230.4 | S12: =HR_Data[[#This Row],[Salary]]+HR_Data[[#This Row],[Bonus Amount]] -> 46534.4 | T12: =IF(HR_Data[[#This Row],[Attrition]]="Yes","Inactive","Active") -> Active | U12: {=_xlfn.IFS(HR_Data[[#This Row],[Salary]]>=100000,"A",HR_Data[[#This Row],[Salary]]>=70000,"B",HR_Data[[#This Row],[Salary]]>=50000,"C",TRUE(),"D")} -> D | V12: {=_xlfn.IFS(HR_Data[[#This Row],[Experience]]>=15,"Expert",HR_Data[[#This Row],[Experience]]>=8,"Senior",HR_Data[[#This Row],[Experience]]>=3,"Mid-Level",TRUE(),"Junior")} -> Mid-Level
A13: EMP0012 | B13: Rahul Jain | C13: Finance | D13: Male | E13: 30 | F13: 53646 | G13: 7 | H13: 19-Jul-2018 | I13: Hyderabad | J13: Good | K13: No | L13: {=_xlfn.IFS(HR_Data[[#This Row],[Experience]]<2,"0-2 Years",HR_Data[[#This Row],[Experience]]<5,"2-5 Years",HR_Data[[#This Row],[Experience]]<10,"5-10 Years",TRUE(),"10+ Years")} -> 5-10 Years | M13: {=_xlfn.IFS(HR_Data[[#This Row],[Salary]]<40000,"Low",HR_Data[[#This Row],[Salary]]<70000,"Medium",HR_Data[[#This Row],[Salary]]<100000,"High",TRUE(),"Very High")} -> Medium | N13: {=_xlfn.IFS(HR_Data[[#This Row],[Age]]<25,"18-24",HR_Data[[#This Row],[Age]]<35,"25-34",HR_Data[[#This Row],[Age]]<45,"35-44",TRUE(),"45+")} -> 25-34 | O13: =YEAR(HR_Data[[#This Row],[Joining Date]]) -> 2018 | P13: =TEXT(HR_Data[[#This Row],[Joining Date]],"mmmm") -> July | Q13: {=_xlfn.IFS(HR_Data[[#This Row],[Performance Rating]]="Excellent",20%,HR_Data[[#This Row],[Performance Rating]]="Very Good",15%,HR_Data[[#This Row],[Performance Rating]]="Good",10%,HR_Data[[#This Row],[Performance Rating]]="Average",5%,TRUE(),0%)} -> 0.1 | R13: =HR_Data[[#This Row],[Salary]]*HR_Data[[#This Row],[Bonus %]] -> 5364.6 | S13: =HR_Data[[#This Row],[Salary]]+HR_Data[[#This Row],[Bonus Amount]] -> 59010.6 | T13: =IF(HR_Data[[#This Row],[Attrition]]="Yes","Inactive","Active") -> Active | U13: {=_xlfn.IFS(HR_Data[[#This Row],[Salary]]>=100000,"A",HR_Data[[#This Row],[Salary]]>=70000,"B",HR_Data[[#This Row],[Salary]]>=50000,"C",TRUE(),"D")} -> C | V13: {=_xlfn.IFS(HR_Data[[#This Row],[Experience]]>=15,"Expert",HR_Data[[#This Row],[Experience]]>=8,"Senior",HR_Data[[#This Row],[Experience]]>=3,"Mid-Level",TRUE(),"Junior")} -> Mid-Level
... A1001: EMP1000 | B1001: Riya Gupta | C1001: Marketing | D1001: Male | E1001: 41 | F1001: 74605 | G1001: 17 | H1001: 07-Feb-2016 | I1001: Jaipur | J1001: Good | K1001: No | L1001: {=_xlfn.IFS(HR_Data[[#This Row],[Experience]]<2,"0-2 Years",HR_Data[[#This Row],[Experience]]<5,"2-5 Years",HR_Data[[#This Row],[Experience]]<10,"5-10 Years",TRUE(),"10+ Years")} -> 10+ Years | M1001: {=_xlfn.IFS(HR_Data[[#This Row],[Salary]]<40000,"Low",HR_Data[[#This Row],[Salary]]<70000,"Medium",HR_Data[[#This Row],[Salary]]<100000,"High",TRUE(),"Very High")} -> High | N1001: {=_xlfn.IFS(HR_Data[[#This Row],[Age]]<25,"18-24",HR_Data[[#This Row],[Age]]<35,"25-34",HR_Data[[#This Row],[Age]]<45,"35-44",TRUE(),"45+")} -> 35-44 | O1001: =YEAR(HR_Data[[#This Row],[Joining Date]]) -> 2016 | P1001: =TEXT(HR_Data[[#This Row],[Joining Date]],"mmmm") -> February | Q1001: {=_xlfn.IFS(HR_Data[[#This Row],[Performance Rating]]="Excellent",20%,HR_Data[[#This Row],[Performance Rating]]="Very Good",15%,HR_Data[[#This Row],[Performance Rating]]="Good",10%,HR_Data[[#This Row],[Performance Rating]]="Average",5%,TRUE(),0%)} -> 0.1 | R1001: =HR_Data[[#This Row],[Salary]]*HR_Data[[#This Row],[Bonus %]] -> 7460.5 | S1001: =HR_Data[[#This Row],[Salary]]+HR_Data[[#This Row],[Bonus Amount]] -> 82065.5 | T1001: =IF(HR_Data[[#This Row],[Attrition]]="Yes","Inactive","Active") -> Active | U1001: {=_xlfn.IFS(HR_Data[[#This Row],[Salary]]>=100000,"A",HR_Data[[#This Row],[Salary]]>=70000,"B",HR_Data[[#This Row],[Salary]]>=50000,"C",TRUE(),"D")} -> B | V1001: {=_xlfn.IFS(HR_Data[[#This Row],[Experience]]>=15,"Expert",HR_Data[[#This Row],[Experience]]>=8,"Senior",HR_Data[[#This Row],[Experience]]>=3,"Mid-Level",TRUE(),"Junior")} -> Expert

Sheet Pivot
A3: Department | B3: Department-wise Employees | F3: Department | G3: Average of Salary | K3: Gender | L3: Count of Employee ID
A4: Admin | B4: 99 | F4: Admin | G4: 80473.424 | K4: Female | L4: 512
A5: Customer Support | B5: 111 | F5: Customer Support | G5: 80001.486 | K5: Male | L5: 488
A6: Finance | B6: 119 | F6: Finance | G6: 82280.706 | K6: Total Result | L6: 1000
A7: HR | B7: 85 | F7: HR | G7: 90334.918
A8: IT | B8: 91 | F8: IT | G8: 84813.659
A9: Legal | B9: 101 | F9: Legal | G9: 80563.277
A10: Marketing | B10: 84 | F10: Marketing | G10: 89179.119
A11: Operations | B11: 111 | F11: Operations | G11: 83387.55
A12: R&D | B12: 94 | F12: R&D | G12: 84956.085
A13: Sales | B13: 105 | F13: Sales | G13: 77163.705
A14: Total Result | B14: 1000 | F14: Total Result | G14: 83006.965
A20: Count of Employee ID | B20: Attrition | F20: Performance Rating | G20: Count of Employee ID | K20: City | L20: Count of Employee ID
A21: Department | B21: No | C21: Yes | D21: Total Result | F21: Average | G21: 178 | K21: Ahmedabad | L21: 106
A22: Admin | B22: 89 | C22: 10 | D22: 99 | F22: Excellent | G22: 173 | K22: Bengaluru | L22: 101
A23: Customer Support | B23: 94 | C23: 17 | D23: 111 | F23: Good | G23: 312 | K23: Chennai | L23: 96
A24: Finance | B24: 102 | C24: 17 | D24: 119 | F24: Poor | G24: 69 | K24: Delhi | L24: 74
A25: HR | B25: 75 | C25: 10 | D25: 85 | F25: Very Good | G25: 268 | K25: Hyderabad | L25: 124
A26: IT | B26: 81 | C26: 10 | D26: 91 | F26: Total Result | G26: 1000 | K26: Jaipur | L26: 104
A27: Legal | B27: 90 | C27: 11 | D27: 101 | K27: Kolkata | L27: 80
A28: Marketing | B28: 73 | C28: 11 | D28: 84 | K28: Lucknow | L28: 108
A29: Operations | B29: 100 | C29: 11 | D29: 111 | K29: Mumbai | L29: 122
A30: R&D | B30: 82 | C30: 12 | D30: 94 | K30: Pune | L30: 85
A31: Sales | B31: 89 | C31: 16 | D31: 105 | K31: Total Result | L31: 1000
A32: Total Result | B32: 875 | C32: 125 | D32: 1000
A38: Experience Group | B38: Count of Employee ID | F38: Salary Band | G38: Count of Employee ID | K38: Join Year | L38: Count of Employee ID
A39: 0-2 Years | B39: 60 | F39: High | G39: 225 | K39: 2015 | L39: 68
A40: 10+ Years | B40: 702 | F40: Low | G40: 130 | K40: 2016 | L40: 92
A41: 2-5 Years | B41: 76 | F41: Medium | G41: 278 | K41: 2017 | L41: 89
A42: 5-10 Years | B42: 162 | F42: Very High | G42: 367 | K42: 2018 | L42: 86
A43: Total Result | B43: 1000 | F43: Total Result | G43: 1000 | K43: 2019 | L43: 76
K44: 2020 | L44: 101
K45: 2021 | L45: 86
K46: 2022 | L46: 70
K47: 2023 | L47: 99
K48: 2024 | L48: 102
K49: 2025 | L49: 88
K50: 2026 | L50: 43
K51: Total Result | L51: 1000
A56: Age Group | B56: Count of Employee ID
...

Sheet Dashboard
A1: 🧭 HR ANALYTICS DASHBOARD
A3: ="Executive Workforce Intelligence Overview • Report Date: "&TEXT(TODAY(),"dd mmm yyyy") -> Executive Workforce Intelligence Overview • Report Date: 06 Aug 2026
A5: KEY WORKFORCE METRICS | S5: 🎛 FILTERS
A6: 👥 TOTAL EMPLOYEES | D6: ✅ ACTIVE EMPLOYEES | G6: 💰 TOTAL PAYROLL | J6: 📊 AVERAGE SALARY | M6: ⏳ AVG EXPERIENCE | P6: 📉 ATTRITION RATE | S6: Department
S7: All
A8: =COUNTA(HR_Data[Employee ID]) -> 1000 | D8: =_Helpers!D15 -> 875 | G8: =_Helpers!D12 -> 92539200 | J8: =AVERAGE(HR_Data[Salary]) -> 83006.965 | M8: =ROUND(AVERAGE(HR_Data[Experience]),1) -> 17.4 | P8: =COUNTIF(HR_Data[Attrition],"Yes")/COUNTA(HR_Data[Employee ID]) -> 0.125
S9: Gender
S10: All
A12: EXECUTIVE SUMMARY | S12: 📅 JOINING TIMELINE
A13: 🏆 TOP PERFORMER | D13: 💵 HIGHEST SALARY | G13: ⚠️ HIGHEST ATTRITION | J13: 🚹 MALE EMPLOYEES | M13: 🚺 FEMALE EMPLOYEES | S13: 2015 | V13: =Pivot!L39 -> 68
S14: 2016 | V14: =Pivot!L40 -> 92
A15: =_Helpers!D9 -> Sneha Yadav | D15: =MAX(HR_Data[Salary]) -> 148955 | G15: =_Helpers!D2 -> Customer Support | J15: =COUNTIF(HR_Data[Gender],"Male") -> 488 | M15: =COUNTIF(HR_Data[Gender],"Female") -> 512 | S15: 2017 | V15: =Pivot!L41 -> 89
S16: 2018 | V16: =Pivot!L42 -> 86
S17: 2019 | V17: =Pivot!L43 -> 76
S18: 2020 | V18: =Pivot!L44 -> 101
A19: 💡 BUSINESS INSIGHTS | S19: 2021 | V19: =Pivot!L45 -> 86
A20: ="🏆 Top Performer: "&_Helpers!D9&" (₹"&TEXT(_Helpers!D7,"#,##0")&")"&CHAR(10)&"⚠️ Highest Attrition: "&_Helpers!D2&" at "&TEXT(_Helpers!D4,"0.0%")&" of department headcount"&CHAR(10)&"💰 Total Payroll: ₹"&TEXT(_Helpers!D12,"#,##0")&" | Active Employees: "&TEXT(_Helpers!D15,"#,##0")&CHAR(10)&"⚖️ Gender Mix: "&TEXT(Pivot!L5/Pivot!L6,"0.0%")&" Male / "&TEXT(Pivot!L4/Pivot!L6,"0.0%")&" Female" -> 🏆 Top Performer: Sneha Yadav (₹1,48,955) ⚠️ Highest Attrition: Customer Support at 15.3% of department headcount 💰 Total Payroll: ₹9,25,39,200 | Active Employees: 875 ⚖️ Gender Mix: 48.8% Male / 51.2% Female | S20: 2022 | V20: =Pivot!L46 -> 70
S21: 2023 | V21: =Pivot!L47 -> 99
S22: 2024 | V22: =Pivot!L48 -> 102
S23: 2025 | V23: =Pivot!L49 -> 88
S24: 2026 | V24: =Pivot!L50 -> 43
A26: 📊 WORKFORCE ANALYTICS
A67: ="HR Analytics Dashboard • Data refreshed as of "&TEXT(TODAY(),"dd mmm yyyy")&" • Source: HR_Data ("&COUNTA(HR_Data[Employee ID])&" records)" -> HR Analytics Dashboard • Data refreshed as of 06 Aug 2026 • Source: HR_Data (1000 records)

Sheet _Helpers
A1: Department | B1: AttritionRate | D1: Highest Attrition Department
A2: =Pivot!A22 -> Admin | B2: =Pivot!C22/Pivot!D22 -> 0.1010101 | D2: =INDEX(A2:A11,MATCH(MAX(B2:B11),B2:B11,0)) -> Customer Support
A3: =Pivot!A23 -> Customer Support | B3: =Pivot!C23/Pivot!D23 -> 0.15315315 | D3: Highest Attrition Rate
A4: =Pivot!A24 -> Finance | B4: =Pivot!C24/Pivot!D24 -> 0.14285714 | D4: =MAX(B2:B11) -> 0.15315315
A5: =Pivot!A25 -> HR | B5: =Pivot!C25/Pivot!D25 -> 0.11764706
A6: =Pivot!A26 -> IT | B6: =Pivot!C26/Pivot!D26 -> 0.10989011 | D6: Top Performer Max Salary
A7: =Pivot!A27 -> Legal | B7: =Pivot!C27/Pivot!D27 -> 0.10891089 | D7: =_xlfn.MAXIFS(HR_Data[Salary],HR_Data[Performance Rating],"Excellent") -> 148955
A8: =Pivot!A28 -> Marketing | B8: =Pivot!C28/Pivot!D28 -> 0.13095238 | D8: Top Performer Name
A9: =Pivot!A29 -> Operations | B9: =Pivot!C29/Pivot!D29 -> 0.099099099 | D9: =INDEX(HR_Data[Employee Name],MATCH(D7,HR_Data[Salary],0)) -> Sneha Yadav
A10: =Pivot!A30 -> R&D | B10: =Pivot!C30/Pivot!D30 -> 0.12765957
A11: =Pivot!A31 -> Sales | B11: =Pivot!C31/Pivot!D31 -> 0.15238095 | D11: Total Payroll
D12: =SUM(HR_Data[Total Salary]) -> 92539200
D14: Active Employees
D15: =COUNTIF(HR_Data[Employee Status],"Active") -> 875
